Workbook

Sheet Leia-me
A1: SIMULADOR REFORMA TRIBUTÁRIA — SIMPLES NACIONAL: IBS/CBS NO PGDAS x HÍBRIDO — v3 (cClassTrib, segregação por valores e aba Despesas)
A3: 1. OBJETIVO
B4: Comparar, para optantes do Simples Nacional, as duas estratégias do art. 41 da LC 214/2025: (a) CENÁRIO 1 — IBS/CBS por dentro do PGDAS-D; (b) CENÁRIO 2 — HÍBRIDO: demais tributos no Simples e IBS/CBS apurados por fora (regime regular), com reduções de alíquota do cClassTrib nas vendas e créditos sobre as despesas detalhadas.
A6: 2. SEGREGAÇÃO DE RECEITAS POR VALORES (NOVO)
B7: Na aba Dados, informe os VALORES mensais em R$ da receita com ICMS-ST e da receita monofásica de PIS/COFINS — os percentuais de segregação são calculados automaticamente ao lado. O mesmo vale para os produtos com redução de IBS/CBS: informe o valor mensal vendido de produtos enquadrados no cClassTrib com redução e a planilha traz o % de produtos COM redução e o % SEM redução, além dos percentuais de redução (pRedIBS/pRedCBS) do código escolhido.
A9: 3. AMARRAÇÃO COM O cClassTrib
B10: A tabela de Classificação Tributária (IT 2025.002 — Portal Nacional da NF-e) vincula cada cClassTrib a percentuais de redução do IBS (pRedIBS) e da CBS (pRedCBS). A tabela é editável na aba Parametros. A redução entra automaticamente no débito por fora do Cenário 2 e na alíquota destacada na NF-e. PONTO-CHAVE: quem permanece com IBS/CBS por dentro do PGDAS NÃO aproveita as reduções de 30%/60%/alíquota zero — o DAS não muda. Para clientes com produtos beneficiados, o híbrido tende a ficar muito mais atrativo, podendo gerar saldo credor.
A12: 4. ABA DESPESAS — SEGREGADA (NOVO)
B13: As despesas agora ficam em aba própria, segregadas em 4 grupos: (1) vinculadas à Atividade 1 — comércio/indústria; (2) vinculadas à Atividade 2 — serviços; (3) comuns/administrativas com crédito; (4) sem direito a crédito (uso e consumo pessoal — art. 57 da LC 214/2025 — e folha). Para cada linha: valor mensal, S/N de crédito, % de fornecedores do regime regular e % de redução do cClassTrib do FORNECEDOR (o crédito é limitado ao imposto efetivamente destacado). Subtotais por grupo e total geral alimentam o Cenário 2.
A15: 5. COMO USAR
B16: Preencha somente as células em amarelo/fonte azul nas abas Dados e Despesas (e, se quiser, alíquotas de referência e tabela cClassTrib na aba Parametros). Escolha o ano (2027 a 2033). As abas Cen1_PGDAS e Cen2_Hibrido calculam automaticamente; a aba Comparativo consolida e indica a estratégia.
A18: 6. VARIÁVEIS QUE DECIDEM O JOGO
B19: • % de vendas B2B para clientes do regime regular (no híbrido o cliente credita o IBS/CBS destacado; no PGDAS só o valor pago no DAS). • cClassTrib das vendas: reduções só valem por fora. • Volume e perfil das despesas com crédito. • Receitas hoje segregadas (ST/monofásico) perdem o benefício gradualmente no Cenário 1: monofásico acaba em 2027; ST se esvazia com a migração do ICMS para o IBS (2029-2032; extinção em 2033). • Vendas B2C, margem alta e cClassTrib integral favorecem o PGDAS.
A21: 7. PREMISSAS (ajuste conforme regulamentação)
B22: (i) Alíquotas de referência estimadas e editáveis (serão fixadas por resolução do Senado). (ii) Cenário 1: percentuais dos Anexos recalibrados mantendo a alíquota efetiva total do DAS. (iii) Crédito do adquirente no Cenário 1 = IBS/CBS efetivamente pago no DAS. (iv) Transição do IBS: 2029=10%, 2030=20%, 2031=30%, 2032=40%, 2033=100%; CBS integral desde 2027. (v) IBS-teste de 0,1% (2027/2028) desprezado. (vi) Fornecedor do Simples por dentro transfere crédito parcial — ajuste no % de fornecedores do regime regular. (vii) Não modelados: Imposto Seletivo, split payment, Fator R, sublimite de R$ 3,6 mi (há alerta), IPI/ZFM, crédito presumido. (viii) Códigos cClassTrib pré-carregados são exemplos — confirme na tabela oficial vigente do Portal da NF-e.
A24: 8. BASE LEGAL
B25: EC 132/2023 (arts. 125 a 133 do ADCT); LC 214/2025 (art. 41 — opção irretratável para o ano-calendário; arts. 47 e ss. — créditos; art. 57 — vedações; arts. 125 a 145 — alíquota zero e reduções de 30%/60%); IT/NT 2025.002 (tabelas cClassTrib e CST); LC 123/2006 (Anexos I a V).
A27: 9. AVISO
B28: Ferramenta de apoio à decisão com estimativas e premissas simplificadoras. Não substitui a análise do caso concreto nem a legislação vigente.

Sheet Parametros
A1: PARÂMETROS — TABELAS DO SIMPLES, TRANSIÇÃO, ALÍQUOTAS E cClassTrib
A4: TABELAS DO SIMPLES NACIONAL — LC 123/2006, Anexos I a V (alíquotas e repartição consolidada)
A5: Anexo | B5: Faixa | C5: RBT12 de (R$) | D5: RBT12 até (R$) | E5: Alíq. nominal | F5: Parcela a deduzir (R$) | G5: % permanece no DAS (IRPJ/CSLL/CPP/IPI) | H5: % PIS+COFINS (→ CBS) | I5: % ICMS/ISS (→ IBS)
A6: I | B6: 1 | C6: 0 | D6: 180000 | E6: 0.04 | F6: 0 | G6: 0.505 | H6: 0.155 | I6: 0.34
A7: I | B7: 2 | C7: 180000.01 | D7: 360000 | E7: 0.073 | F7: 5940 | G7: 0.505 | H7: 0.155 | I7: 0.34
A8: I | B8: 3 | C8: 360000.01 | D8: 720000 | E8: 0.095 | F8: 13860 | G8: 0.51 | H8: 0.155 | I8: 0.335
A9: I | B9: 4 | C9: 720000.01 | D9: 1800000 | E9: 0.107 | F9: 22500 | G9: 0.51 | H9: 0.155 | I9: 0.335
A10: I | B10: 5 | C10: 1800000 | D10: 3600000 | E10: 0.143 | F10: 87300 | G10: 0.51 | H10: 0.155 | I10: 0.335
A11: I | B11: 6 | C11: 3600000 | D11: 4800000 | E11: 0.19 | F11: 378000 | G11: 0.656 | H11: 0.344 | I11: 0
A12: II | B12: 1 | C12: 0 | D12: 180000 | E12: 0.045 | F12: 0 | G12: 0.54 | H12: 0.14 | I12: 0.32
A13: II | B13: 2 | C13: 180000.01 | D13: 360000 | E13: 0.078 | F13: 5940 | G13: 0.54 | H13: 0.14 | I13: 0.32
A14: II | B14: 3 | C14: 360000.01 | D14: 720000 | E14: 0.1 | F14: 13860 | G14: 0.54 | H14: 0.14 | I14: 0.32
A15: II | B15: 4 | C15: 720000.01 | D15: 1800000 | E15: 0.112 | F15: 22500 | G15: 0.54 | H15: 0.14 | I15: 0.32
A16: II | B16: 5 | C16: 1800000 | D16: 3600000 | E16: 0.147 | F16: 85500 | G16: 0.54 | H16: 0.14 | I16: 0.32
A17: II | B17: 6 | C17: 3600000 | D17: 4800000 | E17: 0.3 | F17: 720000 | G17: 0.745 | H17: 0.255 | I17: 0
... A35: V | B35: 6 | C35: 3600000 | D35: 4800000 | E35: 0.305 | F35: 540000 | G35: 0.8 | H35: 0.2 | I35: 0
A37: Nota: repartição consolidada a partir dos percentuais oficiais dos Anexos da LC 123/2006. Na 6ª faixa o ICMS/ISS é recolhido fora do Simples (0%). No Anexo II a parcela do IPI foi mantida em '% permanece' (redistribuição pendente de regulamentação).
A39: TRANSIÇÃO DA REFORMA — EC 132/2023 / LC 214/2025
A40: Ano | B40: Fase CBS (substitui PIS/COFINS) | C40: Fase IBS (substitui ICMS/ISS)
A41: 2027 | B41: 1 | C41: 0 | D41: 2027/2028: IBS-teste de 0,1% desprezado. 2029-2032: ICMS/ISS reduzidos em 10/20/30/40% e IBS cobrado na mesma proporção. 2033: extinção do ICMS/ISS.
A42: 2028 | B42: 1 | C42: 0
A43: 2029 | B43: 1 | C43: 0.1
A44: 2030 | B44: 1 | C44: 0.2
A45: 2031 | B45: 1 | C45: 0.3
A46: 2032 | B46: 1 | C46: 0.4
A47: 2033 | B47: 1 | C47: 1
A50: ALÍQUOTAS DE REFERÊNCIA DO REGIME REGULAR — EDITÁVEIS (estimativas)
A51: CBS (federal) | B51: 0.088 | C51: Estimativa do Ministério da Fazenda; a alíquota de referência será fixada por resolução do Senado Federal. Atualize quando publicada.
A52: IBS (estadual + municipal) | B52: 0.177
A53: TOTAL IBS + CBS | B53: =B51+B52 -> 0.265
A55: TABELA cClassTrib — CLASSIFICAÇÃO TRIBUTÁRIA E REDUÇÕES DE ALÍQUOTA (EDITÁVEL — IT 2025.002 / Portal NF-e)
A56: cClassTrib | B56: CST | C56: Descrição | D56: pRedIBS (% redução IBS) | E56: pRedCBS (% redução CBS) | F56: Base legal (LC 214/2025)
A57: 000001 | B57: 000 | C57: Tributação integral — regra geral | D57: 0 | E57: 0 | F57: art. 10
A58: 200003 | B58: 200 | C58: Produtos destinados à alimentação humana (red. 60%) | D58: 0.6 | E58: 0.6 | F58: art. 137 / Anexo
A59: 200004 | B59: 200 | C59: Dispositivos médicos (red. 60%) | D59: 0.6 | E59: 0.6 | F59: art. 137 / Anexo
A60: 200039 | B60: 200 | C60: Produções artísticas, culturais e eventos — Anexo X (red. 60%) | D60: 0.6 | E60: 0.6 | F60: art. 137 / Anexo X
A61: RED-60 | B61: 200 | C61: Genérico — alíquota reduzida em 60% (saúde, educação, agro, insumos etc.) | D61: 0.6 | E61: 0.6 | F61: arts. 128-145
A62: RED-30 | B62: 200 | C62: Genérico — profissões intelectuais regulamentadas (red. 30%) | D62: 0.3 | E62: 0.3 | F62: art. 127
A63: ALIQ-ZERO | B63: 200 | C63: Genérico — alíquota zero (cesta básica nacional etc.) | D63: 1 | E63: 1 | F63: arts. 125-126
A64: RED-40-BAR-REST | B64: 200 | C64: Bares, restaurantes e lanchonetes — regime específico (red. 40%; adquirente SEM direito a crédito — marque 'N' na aba Dados) | D64: 0.4 | E64: 0.4 | F64: arts. 273-276
...

Sheet Confronto_Simples
A1: CONFRONTO COM A TABELA DO SIMPLES NACIONAL — LC 123/2006 (validação faixa a faixa)
A3: RBT12 informado (aba Dados) | B3: =Dados!$B$6 -> 822015.76 | C3: A planilha calcula o DAS pela ALÍQUOTA EFETIVA = (RBT12 × nominal − parcela a deduzir) ÷ RBT12. A alíquota nominal é apenas o ponto de partida da fórmula — ela nunca é aplicada diretamente sobre a receita. Compare abaixo, faixa a faixa, com a tabela oficial.
A6: ANEXO I — COMÉRCIO
A7: Faixa | B7: RBT12 de (R$) | C7: RBT12 até (R$) | D7: Alíq. nominal | E7: Parcela a deduzir (R$) | F7: Alíq. EFETIVA no teto da faixa | G7: Alíq. EFETIVA no RBT12 informado | H7: Situação
A8: =Parametros!$B$6 -> 1 | B8: =Parametros!$C$6 -> 0 | C8: =Parametros!$D$6 -> 180000 | D8: =Parametros!$E$6 -> 0.04 | E8: =Parametros!$F$6 -> 0 | F8: =(Parametros!$D$6*Parametros!$E$6-Parametros!$F$6)/Parametros!$D$6 -> 0.04 | G8: =IF(AND(Dados!$B$6>=Parametros!$C$6,Dados!$B$6<=Parametros!$D$6),MAX((Dados!$B$6*Parametros!$E$6-Parametros!$F$6)/Dados!$B$6,0),"") | H8: =IF(AND(Dados!$B$6>=Parametros!$C$6,Dados!$B$6<=Parametros!$D$6),"◄ FAIXA APLICADA","")
A9: =Parametros!$B$7 -> 2 | B9: =Parametros!$C$7 -> 180000.01 | C9: =Parametros!$D$7 -> 360000 | D9: =Parametros!$E$7 -> 0.073 | E9: =Parametros!$F$7 -> 5940 | F9: =(Parametros!$D$7*Parametros!$E$7-Parametros!$F$7)/Parametros!$D$7 -> 0.0565 | G9: =IF(AND(Dados!$B$6>=Parametros!$C$7,Dados!$B$6<=Parametros!$D$7),MAX((Dados!$B$6*Parametros!$E$7-Parametros!$F$7)/Dados!$B$6,0),"") | H9: =IF(AND(Dados!$B$6>=Parametros!$C$7,Dados!$B$6<=Parametros!$D$7),"◄ FAIXA APLICADA","")
A10: =Parametros!$B$8 -> 3 | B10: =Parametros!$C$8 -> 360000.01 | C10: =Parametros!$D$8 -> 720000 | D10: =Parametros!$E$8 -> 0.095 | E10: =Parametros!$F$8 -> 13860 | F10: =(Parametros!$D$8*Parametros!$E$8-Parametros!$F$8)/Parametros!$D$8 -> 0.07575 | G10: =IF(AND(Dados!$B$6>=Parametros!$C$8,Dados!$B$6<=Parametros!$D$8),MAX((Dados!$B$6*Parametros!$E$8-Parametros!$F$8)/Dados!$B$6,0),"") | H10: =IF(AND(Dados!$B$6>=Parametros!$C$8,Dados!$B$6<=Parametros!$D$8),"◄ FAIXA APLICADA","")
A11: =Parametros!$B$9 -> 4 | B11: =Parametros!$C$9 -> 720000.01 | C11: =Parametros!$D$9 -> 1800000 | D11: =Parametros!$E$9 -> 0.107 | E11: =Parametros!$F$9 -> 22500 | F11: =(Parametros!$D$9*Parametros!$E$9-Parametros!$F$9)/Parametros!$D$9 -> 0.0945 | G11: =IF(AND(Dados!$B$6>=Parametros!$C$9,Dados!$B$6<=Parametros!$D$9),MAX((Dados!$B$6*Parametros!$E$9-Parametros!$F$9)/Dados!$B$6,0),"") -> 0.079628262 | H11: =IF(AND(Dados!$B$6>=Parametros!$C$9,Dados!$B$6<=Parametros!$D$9),"◄ FAIXA APLICADA","") -> ◄ FAIXA APLICADA
A12: =Parametros!$B$10 -> 5 | B12: =Parametros!$C$10 -> 1800000 | C12: =Parametros!$D$10 -> 3600000 | D12: =Parametros!$E$10 -> 0.143 | E12: =Parametros!$F$10 -> 87300 | F12: =(Parametros!$D$10*Parametros!$E$10-Parametros!$F$10)/Parametros!$D$10 -> 0.11875 | G12: =IF(AND(Dados!$B$6>=Parametros!$C$10,Dados!$B$6<=Parametros!$D$10),MAX((Dados!$B$6*Parametros!$E$10-Parametros!$F$10)/Dados!$B$6,0),"") | H12: =IF(AND(Dados!$B$6>=Parametros!$C$10,Dados!$B$6<=Parametros!$D$10),"◄ FAIXA APLICADA","")
A13: =Parametros!$B$11 -> 6 | B13: =Parametros!$C$11 -> 3600000 | C13: =Parametros!$D$11 -> 4800000 | D13: =Parametros!$E$11 -> 0.19 | E13: =Parametros!$F$11 -> 378000 | F13: =(Parametros!$D$11*Parametros!$E$11-Parametros!$F$11)/Parametros!$D$11 -> 0.11125 | G13: =IF(AND(Dados!$B$6>=Parametros!$C$11,Dados!$B$6<=Parametros!$D$11),MAX((Dados!$B$6*Parametros!$E$11-Parametros!$F$11)/Dados!$B$6,0),"") | H13: =IF(AND(Dados!$B$6>=Parametros!$C$11,Dados!$B$6<=Parametros!$D$11),"◄ FAIXA APLICADA","")
A15: ANEXO II — INDÚSTRIA
A16: Faixa | B16: RBT12 de (R$) | C16: RBT12 até (R$) | D16: Alíq. nominal | E16: Parcela a deduzir (R$) | F16: Alíq. EFETIVA no teto da faixa | G16: Alíq. EFETIVA no RBT12 informado | H16: Situação
A17: =Parametros!$B$12 -> 1 | B17: =Parametros!$C$12 -> 0 | C17: =Parametros!$D$12 -> 180000 | D17: =Parametros!$E$12 -> 0.045 | E17: =Parametros!$F$12 -> 0 | F17: =(Parametros!$D$12*Parametros!$E$12-Parametros!$F$12)/Parametros!$D$12 -> 0.045 | G17: =IF(AND(Dados!$B$6>=Parametros!$C$12,Dados!$B$6<=Parametros!$D$12),MAX((Dados!$B$6*Parametros!$E$12-Parametros!$F$12)/Dados!$B$6,0),"") | H17: =IF(AND(Dados!$B$6>=Parametros!$C$12,Dados!$B$6<=Parametros!$D$12),"◄ FAIXA APLICADA","")
A18: =Parametros!$B$13 -> 2 | B18: =Parametros!$C$13 -> 180000.01 | C18: =Parametros!$D$13 -> 360000 | D18: =Parametros!$E$13 -> 0.078 | E18: =Parametros!$F$13 -> 5940 | F18: =(Parametros!$D$13*Parametros!$E$13-Parametros!$F$13)/Parametros!$D$13 -> 0.0615 | G18: =IF(AND(Dados!$B$6>=Parametros!$C$13,Dados!$B$6<=Parametros!$D$13),MAX((Dados!$B$6*Parametros!$E$13-Parametros!$F$13)/Dados!$B$6,0),"") | H18: =IF(AND(Dados!$B$6>=Parametros!$C$13,Dados!$B$6<=Parametros!$D$13),"◄ FAIXA APLICADA","")
A19: =Parametros!$B$14 -> 3 | B19: =Parametros!$C$14 -> 360000.01 | C19: =Parametros!$D$14 -> 720000 | D19: =Parametros!$E$14 -> 0.1 | E19: =Parametros!$F$14 -> 13860 | F19: =(Parametros!$D$14*Parametros!$E$14-Parametros!$F$14)/Parametros!$D$14 -> 0.08075 | G19: =IF(AND(Dados!$B$6>=Parametros!$C$14,Dados!$B$6<=Parametros!$D$14),MAX((Dados!$B$6*Parametros!$E$14-Parametros!$F$14)/Dados!$B$6,0),"") | H19: =IF(AND(Dados!$B$6>=Parametros!$C$14,Dados!$B$6<=Parametros!$D$14),"◄ FAIXA APLICADA","")
A20: =Parametros!$B$15 -> 4 | B20: =Parametros!$C$15 -> 720000.01 | C20: =Parametros!$D$15 -> 1800000 | D20: =Parametros!$E$15 -> 0.112 | E20: =Parametros!$F$15 -> 22500 | F20: =(Parametros!$D$15*Parametros!$E$15-Parametros!$F$15)/Parametros!$D$15 -> 0.0995 | G20: =IF(AND(Dados!$B$6>=Parametros!$C$15,Dados!$B$6<=Parametros!$D$15),MAX((Dados!$B$6*Parametros!$E$15-Parametros!$F$15)/Dados!$B$6,0),"") -> 0.084628262 | H20: =IF(AND(Dados!$B$6>=Parametros!$C$15,Dados!$B$6<=Parametros!$D$15),"◄ FAIXA APLICADA","") -> ◄ FAIXA APLICADA
A21: =Parametros!$B$16 -> 5 | B21: =Parametros!$C$16 -> 1800000 | C21: =Parametros!$D$16 -> 3600000 | D21: =Parametros!$E$16 -> 0.147 | E21: =Parametros!$F$16 -> 85500 | F21: =(Parametros!$D$16*Parametros!$E$16-Parametros!$F$16)/Parametros!$D$16 -> 0.12325 | G21: =IF(AND(Dados!$B$6>=Parametros!$C$16,Dados!$B$6<=Parametros!$D$16),MAX((Dados!$B$6*Parametros!$E$16-Parametros!$F$16)/Dados!$B$6,0),"") | H21: =IF(AND(Dados!$B$6>=Parametros!$C$16,Dados!$B$6<=Parametros!$D$16),"◄ FAIXA APLICADA","")
A22: =Parametros!$B$17 -> 6 | B22: =Parametros!$C$17 -> 3600000 | C22: =Parametros!$D$17 -> 4800000 | D22: =Parametros!$E$17 -> 0.3 | E22: =Parametros!$F$17 -> 720000 | F22: =(Parametros!$D$17*Parametros!$E$17-Parametros!$F$17)/Parametros!$D$17 -> 0.15 | G22: =IF(AND(Dados!$B$6>=Parametros!$C$17,Dados!$B$6<=Parametros!$D$17),MAX((Dados!$B$6*Parametros!$E$17-Parametros!$F$17)/Dados!$B$6,0),"") | H22: =IF(AND(Dados!$B$6>=Parametros!$C$17,Dados!$B$6<=Parametros!$D$17),"◄ FAIXA APLICADA","")
A24: ANEXO III — SERVIÇOS
A25: Faixa | B25: RBT12 de (R$) | C25: RBT12 até (R$) | D25: Alíq. nominal | E25: Parcela a deduzir (R$) | F25: Alíq. EFETIVA no teto da faixa | G25: Alíq. EFETIVA no RBT12 informado | H25: Situação
A26: =Parametros!$B$18 -> 1 | B26: =Parametros!$C$18 -> 0 | C26: =Parametros!$D$18 -> 180000 | D26: =Parametros!$E$18 -> 0.06 | E26: =Parametros!$F$18 -> 0 | F26: =(Parametros!$D$18*Parametros!$E$18-Parametros!$F$18)/Parametros!$D$18 -> 0.06 | G26: =IF(AND(Dados!$B$6>=Parametros!$C$18,Dados!$B$6<=Parametros!$D$18),MAX((Dados!$B$6*Parametros!$E$18-Parametros!$F$18)/Dados!$B$6,0),"") | H26: =IF(AND(Dados!$B$6>=Parametros!$C$18,Dados!$B$6<=Parametros!$D$18),"◄ FAIXA APLICADA","")
A27: =Parametros!$B$19 -> 2 | B27: =Parametros!$C$19 -> 180000.01 | C27: =Parametros!$D$19 -> 360000 | D27: =Parametros!$E$19 -> 0.112 | E27: =Parametros!$F$19 -> 9360 | F27: =(Parametros!$D$19*Parametros!$E$19-Parametros!$F$19)/Parametros!$D$19 -> 0.086 | G27: =IF(AND(Dados!$B$6>=Parametros!$C$19,Dados!$B$6<=Parametros!$D$19),MAX((Dados!$B$6*Parametros!$E$19-Parametros!$F$19)/Dados!$B$6,0),"") | H27: =IF(AND(Dados!$B$6>=Parametros!$C$19,Dados!$B$6<=Parametros!$D$19),"◄ FAIXA APLICADA","")
A28: =Parametros!$B$20 -> 3 | B28: =Parametros!$C$20 -> 360000.01 | C28: =Parametros!$D$20 -> 720000 | D28: =Parametros!$E$20 -> 0.135 | E28: =Parametros!$F$20 -> 17640 | F28: =(Parametros!$D$20*Parametros!$E$20-Parametros!$F$20)/Parametros!$D$20 -> 0.1105 | G28: =IF(AND(Dados!$B$6>=Parametros!$C$20,Dados!$B$6<=Parametros!$D$20),MAX((Dados!$B$6*Parametros!$E$20-Parametros!$F$20)/Dados!$B$6,0),"") | H28: =IF(AND(Dados!$B$6>=Parametros!$C$20,Dados!$B$6<=Parametros!$D$20),"◄ FAIXA APLICADA","")
A29: =Parametros!$B$21 -> 4 | B29: =Parametros!$C$21 -> 720000.01 | C29: =Parametros!$D$21 -> 1800000 | D29: =Parametros!$E$21 -> 0.16 | E29: =Parametros!$F$21 -> 35640 | F29: =(Parametros!$D$21*Parametros!$E$21-Parametros!$F$21)/Parametros!$D$21 -> 0.1402 | G29: =IF(AND(Dados!$B$6>=Parametros!$C$21,Dados!$B$6<=Parametros!$D$21),MAX((Dados!$B$6*Parametros!$E$21-Parametros!$F$21)/Dados!$B$6,0),"") -> 0.11664317 | H29: =IF(AND(Dados!$B$6>=Parametros!$C$21,Dados!$B$6<=Parametros!$D$21),"◄ FAIXA APLICADA","") -> ◄ FAIXA APLICADA
A30: =Parametros!$B$22 -> 5 | B30: =Parametros!$C$22 -> 1800000 | C30: =Parametros!$D$22 -> 3600000 | D30: =Parametros!$E$22 -> 0.21 | E30: =Parametros!$F$22 -> 125640 | F30: =(Parametros!$D$22*Parametros!$E$22-Parametros!$F$22)/Parametros!$D$22 -> 0.1751 | G30: =IF(AND(Dados!$B$6>=Parametros!$C$22,Dados!$B$6<=Parametros!$D$22),MAX((Dados!$B$6*Parametros!$E$22-Parametros!$F$22)/Dados!$B$6,0),"") | H30: =IF(AND(Dados!$B$6>=Parametros!$C$22,Dados!$B$6<=Parametros!$D$22),"◄ FAIXA APLICADA","")
A31: =Parametros!$B$23 -> 6 | B31: =Parametros!$C$23 -> 3600000 | C31: =Parametros!$D$23 -> 4800000 | D31: =Parametros!$E$23 -> 0.33 | E31: =Parametros!$F$23 -> 648000 | F31: =(Parametros!$D$23*Parametros!$E$23-Parametros!$F$23)/Parametros!$D$23 -> 0.195 | G31: =IF(AND(Dados!$B$6>=Parametros!$C$23,Dados!$B$6<=Parametros!$D$23),MAX((Dados!$B$6*Parametros!$E$23-Parametros!$F$23)/Dados!$B$6,0),"") | H31: =IF(AND(Dados!$B$6>=Parametros!$C$23,Dados!$B$6<=Parametros!$D$23),"◄ FAIXA APLICADA","")
A33: ANEXO IV — SERVIÇOS
A34: Faixa | B34: RBT12 de (R$) | C34: RBT12 até (R$) | D34: Alíq. nominal | E34: Parcela a deduzir (R$) | F34: Alíq. EFETIVA no teto da faixa | G34: Alíq. EFETIVA no RBT12 informado | H34: Situação
A35: =Parametros!$B$24 -> 1 | B35: =Parametros!$C$24 -> 0 | C35: =Parametros!$D$24 -> 180000 | D35: =Parametros!$E$24 -> 0.045 | E35: =Parametros!$F$24 -> 0 | F35: =(Parametros!$D$24*Parametros!$E$24-Parametros!$F$24)/Parametros!$D$24 -> 0.045 | G35: =IF(AND(Dados!$B$6>=Parametros!$C$24,Dados!$B$6<=Parametros!$D$24),MAX((Dados!$B$6*Parametros!$E$24-Parametros!$F$24)/Dados!$B$6,0),"") | H35: =IF(AND(Dados!$B$6>=Parametros!$C$24,Dados!$B$6<=Parametros!$D$24),"◄ FAIXA APLICADA","")
A36: =Parametros!$B$25 -> 2 | B36: =Parametros!$C$25 -> 180000.01 | C36: =Parametros!$D$25 -> 360000 | D36: =Parametros!$E$25 -> 0.09 | E36: =Parametros!$F$25 -> 8100 | F36: =(Parametros!$D$25*Parametros!$E$25-Parametros!$F$25)/Parametros!$D$25 -> 0.0675 | G36: =IF(AND(Dados!$B$6>=Parametros!$C$25,Dados!$B$6<=Parametros!$D$25),MAX((Dados!$B$6*Parametros!$E$25-Parametros!$F$25)/Dados!$B$6,0),"") | H36: =IF(AND(Dados!$B$6>=Parametros!$C$25,Dados!$B$6<=Parametros!$D$25),"◄ FAIXA APLICADA","")
A37: =Parametros!$B$26 -> 3 | B37: =Parametros!$C$26 -> 360000.01 | C37: =Parametros!$D$26 -> 720000 | D37: =Parametros!$E$26 -> 0.102 | E37: =Parametros!$F$26 -> 12420 | F37: =(Parametros!$D$26*Parametros!$E$26-Parametros!$F$26)/Parametros!$D$26 -> 0.08475 | G37: =IF(AND(Dados!$B$6>=Parametros!$C$26,Dados!$B$6<=Parametros!$D$26),MAX((Dados!$B$6*Parametros!$E$26-Parametros!$F$26)/Dados!$B$6,0),"") | H37: =IF(AND(Dados!$B$6>=Parametros!$C$26,Dados!$B$6<=Parametros!$D$26),"◄ FAIXA APLICADA","")
A38: =Parametros!$B$27 -> 4 | B38: =Parametros!$C$27 -> 720000.01 | C38: =Parametros!$D$27 -> 1800000 | D38: =Parametros!$E$27 -> 0.14 | E38: =Parametros!$F$27 -> 39780 | F38: =(Parametros!$D$27*Parametros!$E$27-Parametros!$F$27)/Parametros!$D$27 -> 0.1179 | G38: =IF(AND(Dados!$B$6>=Parametros!$C$27,Dados!$B$6<=Parametros!$D$27),MAX((Dados!$B$6*Parametros!$E$27-Parametros!$F$27)/Dados!$B$6,0),"") -> 0.091606767 | H38: =IF(AND(Dados!$B$6>=Parametros!$C$27,Dados!$B$6<=Parametros!$D$27),"◄ FAIXA APLICADA","") -> ◄ FAIXA APLICADA
A39: =Parametros!$B$28 -> 5 | B39: =Parametros!$C$28 -> 1800000 | C39: =Parametros!$D$28 -> 3600000 | D39: =Parametros!$E$28 -> 0.22 | E39: =Parametros!$F$28 -> 183780 | F39: =(Parametros!$D$28*Parametros!$E$28-Parametros!$F$28)/Parametros!$D$28 -> 0.16895 | G39: =IF(AND(Dados!$B$6>=Parametros!$C$28,Dados!$B$6<=Parametros!$D$28),MAX((Dados!$B$6*Parametros!$E$28-Parametros!$F$28)/Dados!$B$6,0),"") | H39: =IF(AND(Dados!$B$6>=Parametros!$C$28,Dados!$B$6<=Parametros!$D$28),"◄ FAIXA APLICADA","")
A40: =Parametros!$B$29 -> 6 | B40: =Parametros!$C$29 -> 3600000 | C40: =Parametros!$D$29 -> 4800000 | D40: =Parametros!$E$29 -> 0.33 | E40: =Parametros!$F$29 -> 828000 | F40: =(Parametros!$D$29*Parametros!$E$29-Parametros!$F$29)/Parametros!$D$29 -> 0.1575 | G40: =IF(AND(Dados!$B$6>=Parametros!$C$29,Dados!$B$6<=Parametros!$D$29),MAX((Dados!$B$6*Parametros!$E$29-Parametros!$F$29)/Dados!$B$6,0),"") | H40: =IF(AND(Dados!$B$6>=Parametros!$C$29,Dados!$B$6<=Parametros!$D$29),"◄ FAIXA APLICADA","")
A42: ANEXO V — SERVIÇOS
A43: Faixa | B43: RBT12 de (R$) | C43: RBT12 até (R$) | D43: Alíq. nominal | E43: Parcela a deduzir (R$) | F43: Alíq. EFETIVA no teto da faixa | G43: Alíq. EFETIVA no RBT12 informado | H43: Situação
A44: =Parametros!$B$30 -> 1 | B44: =Parametros!$C$30 -> 0 | C44: =Parametros!$D$30 -> 180000 | D44: =Parametros!$E$30 -> 0.155 | E44: =Parametros!$F$30 -> 0 | F44: =(Parametros!$D$30*Parametros!$E$30-Parametros!$F$30)/Parametros!$D$30 -> 0.155 | G44: =IF(AND(Dados!$B$6>=Parametros!$C$30,Dados!$B$6<=Parametros!$D$30),MAX((Dados!$B$6*Parametros!$E$30-Parametros!$F$30)/Dados!$B$6,0),"") | H44: =IF(AND(Dados!$B$6>=Parametros!$C$30,Dados!$B$6<=Parametros!$D$30),"◄ FAIXA APLICADA","")
A45: =Parametros!$B$31 -> 2 | B45: =Parametros!$C$31 -> 180000.01 | C45: =Parametros!$D$31 -> 360000 | D45: =Parametros!$E$31 -> 0.18 | E45: =Parametros!$F$31 -> 4500 | F45: =(Parametros!$D$31*Parametros!$E$31-Parametros!$F$31)/Parametros!$D$31 -> 0.1675 | G45: =IF(AND(Dados!$B$6>=Parametros!$C$31,Dados!$B$6<=Parametros!$D$31),MAX((Dados!$B$6*Parametros!$E$31-Parametros!$F$31)/Dados!$B$6,0),"") | H45: =IF(AND(Dados!$B$6>=Parametros!$C$31,Dados!$B$6<=Parametros!$D$31),"◄ FAIXA APLICADA","")
A46: =Parametros!$B$32 -> 3 | B46: =Parametros!$C$32 -> 360000.01 | C46: =Parametros!$D$32 -> 720000 | D46: =Parametros!$E$32 -> 0.195 | E46: =Parametros!$F$32 -> 9900 | F46: =(Parametros!$D$32*Parametros!$E$32-Parametros!$F$32)/Parametros!$D$32 -> 0.18125 | G46: =IF(AND(Dados!$B$6>=Parametros!$C$32,Dados!$B$6<=Parametros!$D$32),MAX((Dados!$B$6*Parametros!$E$32-Parametros!$F$32)/Dados!$B$6,0),"") | H46: =IF(AND(Dados!$B$6>=Parametros!$C$32,Dados!$B$6<=Parametros!$D$32),"◄ FAIXA APLICADA","")
A47: =Parametros!$B$33 -> 4 | B47: =Parametros!$C$33 -> 720000.01 | C47: =Parametros!$D$33 -> 1800000 | D47: =Parametros!$E$33 -> 0.205 | E47: =Parametros!$F$33 -> 17100 | F47: =(Parametros!$D$33*Parametros!$E$33-Parametros!$F$33)/Parametros!$D$33 -> 0.1955 | G47: =IF(AND(Dados!$B$6>=Parametros!$C$33,Dados!$B$6<=Parametros!$D$33),MAX((Dados!$B$6*Parametros!$E$33-Parametros!$F$33)/Dados!$B$6,0),"") -> 0.18419748 | H47: =IF(AND(Dados!$B$6>=Parametros!$C$33,Dados!$B$6<=Parametros!$D$33),"◄ FAIXA APLICADA","") -> ◄ FAIXA APLICADA
...

Sheet Dados
A1: DADOS DO CLIENTE — PREENCHA AS CÉLULAS EM AMARELO (percentuais em cinza são calculados)
A3: IDENTIFICAÇÃO
A4: Cliente | B4: PLANT FLOR
A5: Ano da simulação | B5: 2027 | E5: Escolha 2027 a 2033 para ver o efeito da transição.
A6: RBT12 — receita bruta acumulada 12 meses (R$) | B6: 822015.76
A7: Verificação do sublimite estadual | B7: =IF(B6>3600000,"ATENÇÃO: acima do sublimite — ICMS/ISS já fora do DAS","OK") -> OK
A8: Coerência RBT12 × receita mensal informada | B8: =IF(OR(B6=0,B12+B24=0),"—",IF(ABS(B6-12*(B12+B24))/B6>0.2,"ATENÇÃO: RBT12 difere de 12× a receita mensal — a faixa/alíquota pode não refletir o cliente","OK")) -> ATENÇÃO: RBT12 difere de 12× a receita mensal — a faixa/alíquota pode não refletir o cliente
A10: ATIVIDADE 1 — COMÉRCIO / INDÚSTRIA
A11: Anexo do Simples | B11: I | E11: I = comércio; II = indústria.
A12: Receita mensal TOTAL (R$) | B12: 96127
A13: Receita com ICMS-ST hoje (R$/mês) | B13: 190358.24 | C13: =IF($B$12>0,B13/$B$12,0) -> 1.9802786 | E13: → % da receita calculado na coluna C.
A14: Receita monofásica de PIS/COFINS hoje (R$/mês) | B14: 0 | C14: =IF($B$12>0,B14/$B$12,0) -> 0 | E14: → % da receita calculado na coluna C.
A15: % das receitas concentradas que PERMANECEM concentradas | B15: 0 | E15: Regra geral: 0%. Use >0% p/ combustíveis e regimes específicos.
A16: cClassTrib dos produtos COM redução de IBS/CBS | B16: RED-40-BAR-REST | C16: =IFERROR(VLOOKUP(B16,Parametros!$A$57:$E$66,4,FALSE()),0) -> 0.4 | D16: =IFERROR(VLOOKUP(B16,Parametros!$A$57:$E$66,5,FALSE()),0) -> 0.4 | E16: pRedIBS e pRedCBS do código →
A17: Receita mensal de produtos COM redução de IBS/CBS (R$) | B17: 60000 | C17: =IF($B$12>0,B17/$B$12,0) -> 0.62417427 | E17: → % de produtos COM redução calculado na coluna C.
A18: % de produtos SEM redução de IBS/CBS (calculado) | C18: =1-C17 -> 0.37582573 | E18: Tratados como tributação integral (000001).
A19: Vendas geram crédito ao adquirente? (S/N) | B19: S | E19: Marque 'N' p/ bares e restaurantes — art. 276 da LC 214/2025 veda o crédito ao adquirente.
A20: Exclusões da base por fora (R$/mês): gorjetas repassadas + retenções de delivery | B20: 0 | E20: Arts. 274, p.ú., LC 214/2025 e 399 do Dec. 12.955/26 (gorjeta até 15%); exige segregação no documento fiscal.
A22: ATIVIDADE 2 — SERVIÇOS
A23: Anexo do Simples | B23: III | E23: III, IV ou V (avalie o Fator R).
A24: Receita mensal TOTAL (R$) | B24: 50000
A25: Receita com ICMS-ST hoje (R$/mês) | B25: 0 | C25: =IF($B$24>0,B25/$B$24,0) -> 0 | E25: → % da receita calculado na coluna C.
A26: Receita monofásica de PIS/COFINS hoje (R$/mês) | B26: 0 | C26: =IF($B$24>0,B26/$B$24,0) -> 0 | E26: → % da receita calculado na coluna C.
A27: % das receitas concentradas que PERMANECEM concentradas | B27: 0 | E27: Regra geral: 0%. Use >0% p/ combustíveis e regimes específicos.
A28: cClassTrib dos produtos COM redução de IBS/CBS | B28: 000001 | C28: =IFERROR(VLOOKUP(B28,Parametros!$A$57:$E$66,4,FALSE()),0) -> 0 | D28: =IFERROR(VLOOKUP(B28,Parametros!$A$57:$E$66,5,FALSE()),0) -> 0 | E28: pRedIBS e pRedCBS do código →
A29: Receita mensal de produtos COM redução de IBS/CBS (R$) | B29: 0 | C29: =IF($B$24>0,B29/$B$24,0) -> 0 | E29: → % de produtos COM redução calculado na coluna C.
A30: % de produtos SEM redução de IBS/CBS (calculado) | C30: =1-C29 -> 1 | E30: Tratados como tributação integral (000001).
A31: Vendas geram crédito ao adquirente? (S/N) | B31: S | E31: Marque 'N' p/ bares e restaurantes — art. 276 da LC 214/2025 veda o crédito ao adquirente.
A32: Exclusões da base por fora (R$/mês): gorjetas repassadas + retenções de delivery | B32: 0 | E32: Arts. 274, p.ú., LC 214/2025 e 399 do Dec. 12.955/26 (gorjeta até 15%); exige segregação no documento fiscal.
A34: PERFIL DE CLIENTES
A35: % das vendas B2B para clientes do regime regular (aproveitam crédito) | B35: 0.6 | E35: Variável decisiva: no híbrido o cliente credita o IBS/CBS destacado.

Sheet Despesas
A1: DESPESAS MENSAIS SEGREGADAS — CRÉDITOS DE IBS/CBS NO CENÁRIO HÍBRIDO
A3: Crédito = Valor × (S/N) × % fornecedor regime regular × (1 − redução cClassTrib do fornecedor) × alíquota IBS/CBS vigente no ano (Cen2!B6). Fornecedor com cClassTrib reduzido destaca menos imposto → crédito menor. Fornecedor do Simples por dentro transfere só o valor pago no DAS (ajuste na coluna D).
A6: Categoria de despesa | B6: Valor mensal (R$) | C6: Crédito? (S/N) | D6: % fornecedor regime regular | E6: % redução cClassTrib do fornecedor | F6: Crédito estimado (R$)
A8: 1. DESPESAS VINCULADAS À ATIVIDADE 1 — COMÉRCIO/INDÚSTRIA
A9: Mercadorias para revenda | B9: 60000 | C9: S | D9: 0.85 | E9: 0 | F9: =B9*IF(C9="S",1,0)*D9*(1-E9)*Cen2_Hibrido!$B$6 -> 4488
A10: Matérias-primas e insumos de produção | B10: 20000 | C10: S | D10: 0.8 | E10: 0 | F10: =B10*IF(C10="S",1,0)*D10*(1-E10)*Cen2_Hibrido!$B$6 -> 1408
A11: Embalagens | B11: 5000 | C11: S | D11: 0.8 | E11: 0 | F11: =B11*IF(C11="S",1,0)*D11*(1-E11)*Cen2_Hibrido!$B$6 -> 352
A12: Fretes sobre compras e vendas | B12: 8000 | C12: S | D12: 0.7 | E12: 0 | F12: =B12*IF(C12="S",1,0)*D12*(1-E12)*Cen2_Hibrido!$B$6 -> 492.8
A13: Subtotal | B13: =SUM(B9:B12) -> 93000 | F13: =SUM(F9:F12) -> 6740.8
A15: 2. DESPESAS VINCULADAS À ATIVIDADE 2 — SERVIÇOS
A16: Materiais aplicados na prestação de serviços | B16: 3000 | C16: S | D16: 0.8 | E16: 0 | F16: =B16*IF(C16="S",1,0)*D16*(1-E16)*Cen2_Hibrido!$B$6 -> 211.2
A17: Serviços subcontratados de PJ | B17: 2000 | C17: S | D17: 0.7 | E17: 0 | F17: =B17*IF(C17="S",1,0)*D17*(1-E17)*Cen2_Hibrido!$B$6 -> 123.2
A18: Subtotal | B18: =SUM(B16:B17) -> 5000 | F18: =SUM(F16:F17) -> 334.4
A20: 3. DESPESAS COMUNS / ADMINISTRATIVAS COM CRÉDITO
A21: Energia elétrica | B21: 6000 | C21: S | D21: 1 | E21: 0 | F21: =B21*IF(C21="S",1,0)*D21*(1-E21)*Cen2_Hibrido!$B$6 -> 528
A22: Aluguel de imóvel (locador PJ contribuinte) | B22: 8000 | C22: S | D22: 1 | E22: 0 | F22: =B22*IF(C22="S",1,0)*D22*(1-E22)*Cen2_Hibrido!$B$6 -> 704
A23: Serviços tomados de PJ (TI, marketing, manutenção...) | B23: 6000 | C23: S | D23: 0.7 | E23: 0 | F23: =B23*IF(C23="S",1,0)*D23*(1-E23)*Cen2_Hibrido!$B$6 -> 369.6
A24: Telecomunicações | B24: 2000 | C24: S | D24: 1 | E24: 0 | F24: =B24*IF(C24="S",1,0)*D24*(1-E24)*Cen2_Hibrido!$B$6 -> 176
A25: Combustíveis (regime monofásico) | B25: 3000 | C25: S | D25: 1 | E25: 0 | F25: =B25*IF(C25="S",1,0)*D25*(1-E25)*Cen2_Hibrido!$B$6 -> 264
A26: Bens do ativo imobilizado (crédito integral e imediato) | B26: 2000 | C26: S | D26: 1 | E26: 0 | F26: =B26*IF(C26="S",1,0)*D26*(1-E26)*Cen2_Hibrido!$B$6 -> 176
A27: Outras despesas com crédito | B27: 0 | C27: S | D27: 1 | E27: 0 | F27: =B27*IF(C27="S",1,0)*D27*(1-E27)*Cen2_Hibrido!$B$6 -> 0
A28: Subtotal | B28: =SUM(B21:B27) -> 27000 | F28: =SUM(F21:F27) -> 2217.6
A30: 4. DESPESAS SEM DIREITO A CRÉDITO
A31: Bens/serviços de USO E CONSUMO PESSOAL — vedado (art. 57) | B31: 3000 | C31: N | D31: 0 | E31: 0 | F31: =B31*IF(C31="S",1,0)*D31*(1-E31)*Cen2_Hibrido!$B$6 -> 0
A32: Folha de salários e pró-labore — sem incidência | B32: 25000 | C32: N | D32: 0 | E32: 0 | F32: =B32*IF(C32="S",1,0)*D32*(1-E32)*Cen2_Hibrido!$B$6 -> 0
A33: Outras despesas sem crédito | B33: 0 | C33: N | D33: 0 | E33: 0 | F33: =B33*IF(C33="S",1,0)*D33*(1-E33)*Cen2_Hibrido!$B$6 -> 0
A34: Subtotal | B34: =SUM(B31:B33) -> 28000 | F34: =SUM(F31:F33) -> 0
A36: TOTAL GERAL DAS DESPESAS | B36: =B13+B18+B28+B34 -> 153000 | F36: =F13+F18+F28+F34 -> 9292.8
A37: Total de despesas COM direito a crédito (base creditável) | B37: =B13+B18+B28 -> 125000

Sheet Cen1_PGDAS
A1: CENÁRIO 1 — SIMPLES INTEGRAL: IBS/CBS RECOLHIDOS POR DENTRO DO PGDAS
A3: Ano da simulação | B3: =Dados!B5 -> 2027
A4: Fase CBS (PIS/COFINS → CBS) | B4: =VLOOKUP(Dados!$B$5,Parametros!$A$41:$C$47,2,FALSE()) -> 1
A5: Fase IBS (ICMS/ISS → IBS) | B5: =VLOOKUP(Dados!$B$5,Parametros!$A$41:$C$47,3,FALSE()) -> 0
A7: APURAÇÃO POR ATIVIDADE
B8: Atividade 1 — Comércio/Ind. | C8: Atividade 2 — Serviços
A9: Anexo | B9: =Dados!$B$11 -> I | C9: =Dados!$B$23 -> III
A10: Receita mensal (R$) | B10: =Dados!$B$12 -> 96127 | C10: =Dados!$B$24 -> 50000
A11: Alíquota NOMINAL da faixa (só referência) | B11: =SUMIFS(Parametros!$E$6:$E$35,Parametros!$A$6:$A$35,B9,Parametros!$C$6:$C$35,"<="&Dados!$B$6,Parametros!$D$6:$D$35,">="&Dados!$B$6) -> 0.107 | C11: =SUMIFS(Parametros!$E$6:$E$35,Parametros!$A$6:$A$35,C9,Parametros!$C$6:$C$35,"<="&Dados!$B$6,Parametros!$D$6:$D$35,">="&Dados!$B$6) -> 0.16
A12: Parcela a deduzir (R$) | B12: =SUMIFS(Parametros!$F$6:$F$35,Parametros!$A$6:$A$35,B9,Parametros!$C$6:$C$35,"<="&Dados!$B$6,Parametros!$D$6:$D$35,">="&Dados!$B$6) -> 22500 | C12: =SUMIFS(Parametros!$F$6:$F$35,Parametros!$A$6:$A$35,C9,Parametros!$C$6:$C$35,"<="&Dados!$B$6,Parametros!$D$6:$D$35,">="&Dados!$B$6) -> 35640
A13: ALÍQUOTA EFETIVA do Simples (usada no cálculo) | B13: =IF(Dados!$B$6>0,MAX((Dados!$B$6*B11-B12)/Dados!$B$6,0),0) -> 0.079628262 | C13: =IF(Dados!$B$6>0,MAX((Dados!$B$6*C11-C12)/Dados!$B$6,0),0) -> 0.11664317
A14: % da alíq. destinado a PIS/COFINS (→CBS) | B14: =SUMIFS(Parametros!$H$6:$H$35,Parametros!$A$6:$A$35,B9,Parametros!$C$6:$C$35,"<="&Dados!$B$6,Parametros!$D$6:$D$35,">="&Dados!$B$6) -> 0.155 | C14: =SUMIFS(Parametros!$H$6:$H$35,Parametros!$A$6:$A$35,C9,Parametros!$C$6:$C$35,"<="&Dados!$B$6,Parametros!$D$6:$D$35,">="&Dados!$B$6) -> 0.166
A15: % da alíq. destinado a ICMS/ISS (→IBS) | B15: =SUMIFS(Parametros!$I$6:$I$35,Parametros!$A$6:$A$35,B9,Parametros!$C$6:$C$35,"<="&Dados!$B$6,Parametros!$D$6:$D$35,">="&Dados!$B$6) -> 0.335 | C15: =SUMIFS(Parametros!$I$6:$I$35,Parametros!$A$6:$A$35,C9,Parametros!$C$6:$C$35,"<="&Dados!$B$6,Parametros!$D$6:$D$35,">="&Dados!$B$6) -> 0.325
A16: Receita sem concentração (R$) | B16: =B10*(1-Dados!$C$13-Dados!$C$14) -> -94231.24 | C16: =C10*(1-Dados!$C$25-Dados!$C$26) -> 50000
A17: Receita com ICMS-ST (R$) | B17: =B10*Dados!$C$13 -> 190358.24 | C17: =C10*Dados!$C$25 -> 0
A18: Receita monofásica (R$) | B18: =B10*Dados!$C$14 -> 0 | C18: =C10*Dados!$C$26 -> 0
A19: Alíq. DAS s/ receita normal | B19: =B13 -> 0.079628262 | C19: =C13 -> 0.11664317
A20: Alíq. DAS s/ receita ST | B20: =B13*(1-B15*((1-$B$5)+$B$5*Dados!$B$15)) -> 0.052952794 | C20: =C13*(1-C15*((1-$B$5)+$B$5*Dados!$B$27)) -> 0.078734138 | D20: Receita ST: mantém o benefício apenas sobre a parcela do ICMS ainda não substituída pelo IBS (e sobre o que permanecer concentrado).
A21: Alíq. DAS s/ receita monofásica | B21: =B13*(1-B14*$B$4*Dados!$B$15) -> 0.079628262 | C21: =C13*(1-C14*$B$4*Dados!$B$27) -> 0.11664317
A22: DAS MENSAL DA ATIVIDADE (R$) | B22: =B16*B19+B17*B20+B18*B21 -> 2576.5308 | C22: =C16*C19+C17*C20+C18*C21 -> 5832.1584 | D22: Premissa: percentuais dos Anexos recalibrados mantendo a alíquota efetiva total. As reduções do cClassTrib NÃO se aplicam por dentro do PGDAS — o DAS não muda.
A23: Crédito de IBS/CBS transferível aos clientes (total, R$) | B23: =B13*(B16*(B14*$B$4+B15*$B$5)+B17*(B14*$B$4+B15*$B$5*(1-Dados!$B$15))+B18*(B14*$B$4*(1-Dados!$B$15)+B15*$B$5)) -> 1186.436 | C23: =C13*(C16*(C14*$B$4+C15*$B$5)+C17*(C14*$B$4+C15*$B$5*(1-Dados!$B$27))+C18*(C14*$B$4*(1-Dados!$B$27)+C15*$B$5)) -> 968.13829 | D23: Crédito do adquirente limitado ao IBS/CBS efetivamente pago no DAS (LC 214/2025).
A24: Crédito transferível — só vendas B2B (R$) | B24: =IF(Dados!$B$19="S",1,0)*B23*Dados!$B$35 -> 711.86161 | C24: =IF(Dados!$B$31="S",1,0)*C23*Dados!$B$35 -> 580.88297
A25: Faixa da tabela aplicada (confira na aba Confronto_Simples) | B25: =SUMIFS(Parametros!$B$6:$B$35,Parametros!$A$6:$A$35,B9,Parametros!$C$6:$C$35,"<="&Dados!$B$6,Parametros!$D$6:$D$35,">="&Dados!$B$6) -> 4 | C25: =SUMIFS(Parametros!$B$6:$B$35,Parametros!$A$6:$A$35,C9,Parametros!$C$6:$C$35,"<="&Dados!$B$6,Parametros!$D$6:$D$35,">="&Dados!$B$6) -> 4
A26: TOTAIS — CENÁRIO 1
A27: DAS TOTAL MENSAL (R$) | B27: =B22+C22 -> 8408.6892
A28: Crédito de IBS/CBS gerado a clientes B2B (R$/mês) | B28: =B24+C24 -> 1292.7446

Sheet Cen2_Hibrido
A1: CENÁRIO 2 — HÍBRIDO: SIMPLES + IBS/CBS POR FORA, COM REDUÇÕES DO cClassTrib
A3: Ano da simulação | B3: =Dados!B5 -> 2027
A4: Fase CBS | B4: =Cen1_PGDAS!B4 -> 1
A5: Fase IBS | B5: =Cen1_PGDAS!B5 -> 0
A6: Alíquota IBS/CBS CHEIA vigente no ano (sem redução) | B6: =Parametros!$B$51*$B$4+Parametros!$B$52*$B$5 -> 0.088
A8: APURAÇÃO POR ATIVIDADE — DAS REDUZIDO E DÉBITO POR FORA
B9: Atividade 1 — Comércio/Ind. | C9: Atividade 2 — Serviços
A10: Receita mensal (R$) | B10: =Cen1_PGDAS!B10 -> 96127 | C10: =Cen1_PGDAS!C10 -> 50000
A11: Receita sem concentração (R$) | B11: =Cen1_PGDAS!B16 -> -94231.24 | C11: =Cen1_PGDAS!C16 -> 50000
A12: Receita com ICMS-ST (R$) | B12: =Cen1_PGDAS!B17 -> 190358.24 | C12: =Cen1_PGDAS!C17 -> 0
A13: Receita monofásica (R$) | B13: =Cen1_PGDAS!B18 -> 0 | C13: =Cen1_PGDAS!C18 -> 0
A14: Alíquota efetiva do Simples | B14: =Cen1_PGDAS!B13 -> 0.079628262 | C14: =Cen1_PGDAS!C13 -> 0.11664317
A15: % parcela → CBS | B15: =Cen1_PGDAS!B14 -> 0.155 | C15: =Cen1_PGDAS!C14 -> 0.166
A16: % parcela → IBS | B16: =Cen1_PGDAS!B15 -> 0.335 | C16: =Cen1_PGDAS!C15 -> 0.325
A17: cClassTrib dos produtos com redução | B17: =Dados!$B$16 -> RED-40-BAR-REST | C17: =Dados!$B$28 -> 000001
A18: % de produtos COM redução (calculado) | B18: =Dados!$C$17 -> 0.62417427 | C18: =Dados!$C$29 -> 0
A19: pRedIBS (redução do IBS) | B19: =IFERROR(VLOOKUP(B17,Parametros!$A$57:$E$66,4,FALSE()),0) -> 0.4 | C19: =IFERROR(VLOOKUP(C17,Parametros!$A$57:$E$66,4,FALSE()),0) -> 0 | D19: Reduções lidas automaticamente da tabela cClassTrib (aba Parametros). Código não encontrado = 0%.
A20: pRedCBS (redução da CBS) | B20: =IFERROR(VLOOKUP(B17,Parametros!$A$57:$E$66,5,FALSE()),0) -> 0.4 | C20: =IFERROR(VLOOKUP(C17,Parametros!$A$57:$E$66,5,FALSE()),0) -> 0
A21: ALÍQ. IBS/CBS DE VENDA da atividade (média c/ redução) | B21: =Parametros!$B$51*$B$4*(1-B20*B18)+Parametros!$B$52*$B$5*(1-B19*B18) -> 0.066029066 | C21: =Parametros!$B$51*$B$4*(1-C20*C18)+Parametros!$B$52*$B$5*(1-C19*C18) -> 0.088 | D21: Média ponderada: alíquota cheia sobre os produtos sem redução + alíquota reduzida sobre os produtos com redução. É a alíquota efetiva destacada nas NF-e.
A22: Alíq. DAS reduzida s/ receita normal | B22: =B14*(1-B15*$B$4-B16*$B$5) -> 0.067285881 | C22: =C14*(1-C15*$B$4-C16*$B$5) -> 0.097280401 | D22: Retiram-se do DAS as parcelas de PIS/COFINS (→CBS) e ICMS/ISS (→IBS) conforme a fase da transição.
A23: Alíq. DAS reduzida s/ receita ST | B23: =B14*(1-B15*$B$4-B16) -> 0.040610414 | C23: =C14*(1-C15*$B$4-C16) -> 0.059371372
A24: Alíq. DAS reduzida s/ receita monofásica | B24: =B22 -> 0.067285881 | C24: =C22 -> 0.097280401 | D24: Monofásico sai do DAS a partir de 2027; ST segue reduzindo o ICMS remanescente.
A25: DAS MENSAL REDUZIDO (R$) | B25: =B11*B22+B12*B23+B13*B24 -> 1390.0948 | C25: =C11*C22+C12*C23+C13*C24 -> 4864.0201
A26: Base do IBS/CBS por fora (R$) | B26: =MAX(B10-(B12+B13)*Dados!$B$15-Dados!$B$20,0) -> 96127 | C26: =MAX(C10-(C12+C13)*Dados!$B$27-Dados!$B$32,0) -> 50000 | D26: Exclui da base a fração que permanecer concentrada (ex.: combustíveis) e as exclusões informadas na aba Dados (gorjetas repassadas até 15% e retenções de delivery — arts. 274 LC 214/25 e 399 Dec. 12.955/26).
A27: Débito de IBS/CBS por fora (R$) | B27: =B26*B21 -> 6347.176 | C27: =C26*C21 -> 4400
A29: APURAÇÃO GLOBAL DO IBS/CBS POR FORA E CARGA TOTAL
A30: Débito total de IBS/CBS (R$) | B30: =B27+C27 -> 10747.176
A31: Crédito s/ despesas detalhadas (R$) | B31: =Despesas!$F$36 -> 9292.8 | D31: Total geral da aba Despesas (subtotais dos grupos 1 a 4).
A32: IBS/CBS a recolher (R$) | B32: =MAX(B30-B31,0) -> 1454.376
A33: Saldo credor do período, se houver (R$) | B33: =MAX(B31-B30,0) -> 0 | D33: Comum quando as vendas têm cClassTrib com redução/alíquota zero e as compras são integrais — passível de ressarcimento.
A34: DAS total reduzido (R$) | B34: =B25+C25 -> 6254.1149
A35: CARGA TOTAL MENSAL — HÍBRIDO (R$) | B35: =B34+B32 -> 7708.4909
A36: Crédito de IBS/CBS gerado a clientes B2B (R$/mês) | B36: =(B27*IF(Dados!$B$19="S",1,0)+C27*IF(Dados!$B$31="S",1,0))*Dados!$B$35 -> 6448.3056 | D36: No híbrido o cliente do regime regular credita o imposto destacado na NF (já líquido da redução do cClassTrib).

Sheet Comparativo
A1: COMPARATIVO E DECISÃO ESTRATÉGICA
A3: Cliente | B3: =Dados!B4 -> PLANT FLOR
A4: Ano da simulação | B4: =Dados!B5 -> 2027
B6: CENÁRIO 1 — Tudo no PGDAS | C6: CENÁRIO 2 — Híbrido (por fora) | D6: Diferença (C2 − C1)
A7: Carga tributária própria — MENSAL (R$) | B7: =Cen1_PGDAS!B27 -> 8408.6892 | C7: =Cen2_Hibrido!B35 -> 7708.4909 | D7: =C7-B7 -> -700.19831
A8: Carga tributária própria — ANUAL (R$) | B8: =B7*12 -> 100904.27 | C8: =C7*12 -> 92501.891 | D8: =C8-B8 -> -8402.3797
A9: Carga própria em % da receita | B9: =IF(Dados!$B$12+Dados!$B$24>0,B7/(Dados!$B$12+Dados!$B$24),0) -> 0.057543706 | C9: =IF(Dados!$B$12+Dados!$B$24>0,C7/(Dados!$B$12+Dados!$B$24),0) -> 0.052751996 | D9: =C9-B9 -> -0.0047917107
A10: Crédito de IBS/CBS gerado a clientes B2B (R$/mês) | B10: =Cen1_PGDAS!B28 -> 1292.7446 | C10: =Cen2_Hibrido!B36 -> 6448.3056 | D10: =C10-B10 -> 5155.561
A11: CARGA LÍQUIDA NA CADEIA (própria − crédito B2B) | B11: =B7-B10 -> 7115.9446 | C11: =C7-C10 -> 1260.1853 | D11: =C11-B11 -> -5855.7593
A12: Alíq. IBS/CBS destacada na NF — Atividade 1 | B12: sem destaque (por dentro) | C12: =Cen2_Hibrido!B21 -> 0.066029066
A13: Alíq. IBS/CBS destacada na NF — Atividade 2 | B13: sem destaque (por dentro) | C13: =Cen2_Hibrido!C21 -> 0.088
A14: Saldo credor mensal no híbrido (se houver) | B14: n/a | C14: =Cen2_Hibrido!B33 -> 0
D15: Valores negativos na coluna D = híbrido melhor.
A17: LEITURA DOS RESULTADOS
A18: Qual cenário custa menos PARA A EMPRESA? | B18: =IF(C7<B7,"HÍBRIDO",IF(C7>B7,"PGDAS","EMPATE")) -> HÍBRIDO
A19: Qual cenário custa menos PARA A CADEIA (empresa + clientes B2B)? | B19: =IF(C11<B11,"HÍBRIDO",IF(C11>B11,"PGDAS","EMPATE")) -> HÍBRIDO
A21: RECOMENDAÇÃO | B21: =IF(AND(C7<=B7,C11<=B11),"HÍBRIDO: menor carga própria E maior competitividade junto a clientes B2B.",IF(AND(B7<=C7,B11<=C11),"PGDAS: permanecer com IBS/CBS por dentro — menor carga própria e a vantagem de crédito ao cliente não compensa.","DEPENDE DO REPASSE: o híbrido custa mais à empresa, porém barateia a compra para o cliente B2B (crédito integral). Vale a pena se for possível precificar/repassar esse crédito ou se a concorrência exigir.")) -> HÍBRIDO: menor carga própria E maior competitividade junto a clientes B2B.
A25: DRIVERS DA DECISÃO (teste nas abas Dados e Despesas)
A26: • cClassTrib com redução (30%/60%) ou alíquota zero nas VENDAS → só beneficia quem está POR FORA: derruba o débito do híbrido, mantém os créditos das compras e pode gerar saldo credor. Quem fica no PGDAS não aproveita a redução.
A27: • ↑ % vendas B2B para regime regular e ↑ despesas com crédito → favorecem o HÍBRIDO.
A28: • ↑ vendas B2C, ↑ margem (pouco insumo) e cClassTrib integral (000001) → favorecem o PGDAS.
A29: • Receitas hoje segregadas (ST/monofásico) perdem o benefício gradualmente no Cenário 1 — recalcule a cada ano da transição (2027→2033).
A30: • BARES E RESTAURANTES (regime específico — arts. 273-276): use o código RED-40-BAR-REST (red. 40%), marque 'N' em 'vendas geram crédito ao adquirente' e lance gorjetas repassadas/retenções de delivery nas exclusões da base — a redução vale só por fora e o cliente PJ não credita.
A31: • Confira as vedações de crédito (uso e consumo pessoal — art. 57) e a redução do cClassTrib dos FORNECEDORES: comprar de quem vende com redução também reduz seu crédito.
A32: • A opção pelo regime regular de IBS/CBS é irretratável para o ano-calendário: simule antes do prazo de opção de cada ano.
